Workbook

Sheet Summary
A2: 11653 Rivera Road - construction takeoff
A4: 563 SF rear addition + WIC/pantry remodel | Approved set dated July 17, 2024 | Quantities only; no prices
A6: Scope | B6: Quantity | C6: Unit | D6: Basis | E6: Notes
A7: New foundation slab | B7: ='Trade takeoff'!D11 -> 563 | C7: SF | D7: Stated | E7: Slab thickness conflict: 6 in vs 4 in.
A8: New continuous / thickened footing lines | B8: ='Trade takeoff'!D10 -> 125.1 | C8: LF | D8: Approximate | E8: 77 exterior + 22.3 interior + 25.8 connection edge.
A9: Isolated pad footings | B9: ='Trade takeoff'!D14 -> 2 | C9: EA | D9: Counted / conflict | E9: 2 pads; plan 1.5 ft square vs detail 2 ft square.
A10: Concrete budget, before 10% overage | B10: ='Trade takeoff'!D16 -> 17.490741 | C10: CY | D10: Allowance | E10: 6 in slab and conservative pad size; confirm engineer details.
A11: Wall framing, gross one-face area | B11: ='Trade takeoff'!D25 -> 1276 | C11: SF | D11: Approximate | E11: Openings included; addition plus existing remodel partitions.
A12: Ceiling joist coverage | B12: ='Trade takeoff'!D31 -> 563 | C12: SF | D12: Stated / plan | E12: New 2x10 @16 in OC; localized existing sistering extra.
A13: New floor joist coverage | B13: 0 | C13: SF | D13: Not shown | E13: 0 SF: new addition is slab on grade.
A14: Drywall, installed area | B14: ='Trade takeoff'!D37 -> 2158.6667 | C14: SF | D14: Approximate | E14: Net wall gypsum + ceilings; shower backer separate.
A15: Stucco, new net field area | B15: ='Trade takeoff'!D40 -> 556 | C15: SF | D15: Calculated | E15: 50 SF repair allowance listed separately.
A16: Roofing, full-house installed area | B16: ='Trade takeoff'!D45 -> 1715.4105 | C16: SF | D16: Approximate | E16: Includes existing house roof work; garage excluded.
A17: Roofing, addition-only subset | B17: ='Trade takeoff'!D44 -> 655.41667 | C17: SF | D17: Approximate | E17: Included in full-house figure; do not add together.
A18: Addition floor coverings | B18: ='Trade takeoff'!D52 -> 525 | C18: SF | D18: Approximate | E18: Clear-floor estimate; 65 SF remodel allowance separate.
A19: Electrical drawn quantities | D19: Counted | E19: 2 GFI, 5 switches, 2 smoke alarms, 1 CO alarm, 2 fan connections.
A20: Plumbing equipment / fixtures | D20: Counted / scheduled | E20: 2 toilets, 2 lavatories, 2 showers, 1 gas tankless heater.
A21: Mechanical equipment | D21: Energy schedule | E21: 1 furnace, 1 split AC, 1 balanced ventilation set, 2 bath fans.
A24: Items requiring clarification before ordering
A26: 1. S-2 slab: detail 1 specifies 6 in; detail 5 specifies 4 in. Concrete budget uses 6 in.
A27: 2. S-2 pads: plan labels 1.5x1.5 ft; detail 6 specifies 24 in square. Budget uses 2x2x2 ft.
A28: 3. Interior footing section is not separately keyed. Budget assumes exterior section; confirm with engineer.
A29: 4. Electrical circuit layout, service load, plumbing routes and HVAC duct sizes/locations are absent.
A30: 5. Pipe/cable/duct quantities marked Allowance are estimating assumptions, not measured routed lengths.
A31: 6. Roof area is scaled and uses average pitch; verify plane areas and existing-house demolition limits.
A32: 7. Finish flooring is not scheduled. Bath tile is assumed; owner must select remaining flooring.
A33: 8. Existing house walls/ceilings beyond identified remodel and garage work are excluded from new finish totals.
A34: 9. No exact lumber cut list, ridge/hip/valley schedule, hardware package or excavation/soil export takeoff.
A35: 10. Source: BSD Stamped Plans BLDR231213011868 - 11653 Rivera Rd.pdf, 13 pages.

Sheet Trade takeoff
A2: Construction quantities - 11653 Rivera Road
A4: Approximate estimating takeoff | Blue inputs are editable | Blank quantity = not measurable from supplied plans
A6: Trade | B6: Item | C6: Unit | D6: Installed qty | E6: Overage | F6: Budget qty | G6: Basis | H6: Sheet / PDF page | J6: Method / limitation
A7: Foundation | B7: Exposed exterior continuous footings | C7: LF | D7: =Measurements!B8 -> 77 | E7: 0 | F7: =D7*(1+E7) -> 77 | G7: Scaled approx. | H7: S-2 / PDF 11 | J7: New exposed perimeter only.
A8: Foundation | B8: Interior longitudinal thickened footing | C8: LF | D8: =Measurements!B9 -> 22.3 | E8: 0 | F8: =D8*(1+E8) -> 22.3 | G8: Scaled approx. | H8: S-2 / PDF 11 | J8: Section assumed same as exterior for budget; obtain engineer confirmation.
A9: Foundation | B9: Slab-to-existing turned-down edge | C9: LF | D9: =Measurements!B10 -> 25.8 | E9: 0 | F9: =D9*(1+E9) -> 25.8 | G9: Scaled approx. | H9: S-2 details 4-5 | J9: 12 in wide x 18 in deep; does not duplicate perimeter.
A10: Foundation | B10: TOTAL new continuous / thickened lines | C10: LF | D10: =SUM(D7:D9) -> 125.1 | E10: 0 | F10: =D10*(1+E10) -> 125.1 | G10: Calculated | H10: S-2 / PDF 11 | J10: Pads listed separately; includes connection edge.
A11: Foundation | B11: New foundation slab area | C11: SF | D11: =Measurements!B5 -> 563 | E11: 0 | F11: =D11*(1+E11) -> 563 | G11: Stated | H11: A-1; S-2 | J11: 6 in budget thickness; plan conflict unresolved.
A12: Foundation | B12: Slab concrete only - 6 in budget | C12: CY | D12: =D11*Measurements!B33/12/27 -> 10.425926 | E12: 0 | F12: =D12*(1+E12) -> 10.425926 | G12: Conflict / allowance | H12: S-2 details 1 and 5 | J12: Does not include footings. Alternative 4 in slab = 6.95 CY.
A13: Foundation | B13: Footing concrete below slab plane | C13: CY | D13: =(D7+D8)*Measurements!B31*(Measurements!B32-Measurements!B33/12)/27+D9*Measurements!B31*(Measurements!B34-Measurements!B33/12)/27 -> 6.4722222 | E13: 0 | F13: =D13*(1+E13) -> 6.4722222 | G13: Allowance | H13: S-2 / PDF 11 | J13: Interior footing section assumed; deducts slab overlap.
A14: Foundation | B14: Isolated pad footings | C14: EA | D14: =Measurements!B35 -> 2 | E14: 0 | F14: =D14*(1+E14) -> 2 | G14: Counted / conflict | H14: S-2 / PDF 11 | J14: Budget 2x2x2 ft each; plan calls 1.5x1.5 ft.
A15: Foundation | B15: Pad concrete | C15: CY | D15: =Measurements!B35*Measurements!B36*Measurements!B36*Measurements!B37/27 -> 0.59259259 | E15: 0 | F15: =D15*(1+E15) -> 0.59259259 | G15: Conflict / allowance | H15: S-2 detail 6 | J15: Full pad volume; existing-slab patch quantity not included.
A16: Foundation | B16: TOTAL concrete budget before overage | C16: CY | D16: =D12+D13+D15 -> 17.490741 | E16: 0.1 | F16: =D16*(1+E16) -> 19.239815 | G16: Allowance | H16: S-2 / PDF 11 | J16: Subject to slab/pad/footing clarification. Add 10% ordering allowance.
A17: Foundation | B17: Clean aggregate base | C17: CY | D17: =Measurements!B5*Measurements!B38/12/27 -> 6.9506173 | E17: 0.1 | F17: =D17*(1+E17) -> 7.645679 | G17: Calculated | H17: S-2 details 1 and 5 | J17: Compacted in-place quantity.
A18: Foundation | B18: Vapor barrier | C18: SF | D18: =Measurements!B5 -> 563 | E18: 0.1 | F18: =D18*(1+E18) -> 619.3 | G18: Conflict / allowance | H18: S-2 details 1 and 5 | J18: Budget 10 mil; detail 5 shows 6 mil.
A19: Foundation | B19: #4 slab reinforcing at 16 in EW | C19: LF | D19: =Measurements!B5*2/(16/12) -> 844.5 | E19: 0.15 | F19: =D19*(1+E19) -> 971.175 | G19: Area allowance | H19: S-2 / PDF 11 | J19: Area method excludes individual bar cuts; 15% laps/cutting.
A20: Foundation | B20: #4 longitudinal footing reinforcing | C20: LF | D20: =(D7+D8)*4+D9*2 -> 448.8 | E20: 0.15 | F20: =D20*(1+E20) -> 516.12 | G20: Allowance | H20: S-2 details 1 and 5 | J20: 4 bars typical exterior; 2 bottom bars connection edge; verify interior section.
A21: Foundation | B21: HDU4 hold-down locations | C21: EA | D21: 11 | E21: 0 | F21: =D21*(1+E21) -> 11 | G21: Counted | H21: S-2 / PDF 11 | J21: Includes cast-in and epoxy anchorage locations; verify anchor types.
A22: Foundation | B22: Slab connection dowels #5 @16 in | C22: EA | D22: =ROUNDUP(D9/(16/12),0)+1 -> 21 | E22: 0 | F22: =D22*(1+E22) -> 21 | G22: Calculated approx. | H22: S-2 detail 5 | J22: Additional footing end dowels per detail 4 not included.
A23: Wall framing | B23: Exterior framed wall, gross one-face area | C23: SF | D23: =Measurements!B8*Measurements!B7 -> 616 | E23: 0 | F23: =D23*(1+E23) -> 616 | G23: Scaled approx. | H23: A-3; S-2 | J23: One face; openings not deducted.
A24: Wall framing | B24: Interior framed wall, gross one-face area | C24: SF | D24: =(Measurements!B11+Measurements!B12)*Measurements!B7 -> 660 | E24: 0 | F24: =D24*(1+E24) -> 660 | G24: Scaled approx. | H24: A-3 / PDF 4 | J24: Addition plus WIC/pantry alterations.
A25: Wall framing | B25: TOTAL wall framing gross one-face area | C25: SF | D25: =D23+D24 -> 1276 | E25: 0 | F25: =D25*(1+E25) -> 1276 | G25: Calculated approx. | H25: A-3 / PDF 4 | J25: Not the two-sided drywall area.
A26: Wall framing | B26: TOTAL new framed wall length | C26: LF | D26: =Measurements!B8+Measurements!B11+Measurements!B12 -> 159.5 | E26: 0 | F26: =D26*(1+E26) -> 159.5 | G26: Scaled approx. | H26: A-3 / PDF 4 | J26: Opening spans included; retained existing walls excluded.
A27: Wall framing | B27: 2x4 common stud budget @16 in OC | C27: EA | D27: =ROUNDUP((Measurements!B8+Measurements!B11+Measurements!B12)/(16/12),0) -> 120 | E27: 0.25 | F27: =D27*(1+E27) -> 150 | G27: Allowance | H27: A-6.1; SD1 | J27: Add 25% for kings, jacks, corners and cripples; not an exact cut list.
A28: Wall framing | B28: Double top plates | C28: LF | D28: =2*(Measurements!B8+Measurements!B11+Measurements!B12) -> 319 | E28: 0.1 | F28: =D28*(1+E28) -> 350.9 | G28: Calculated approx. | H28: SD1 / PDF 13 | J28: DF-L per structural notes.
A29: Wall framing | B29: Bottom plates / PT sill | C29: LF | D29: =Measurements!B8+Measurements!B11+Measurements!B12 -> 159.5 | E29: 0.1 | F29: =D29*(1+E29) -> 175.45 | G29: Calculated approx. | H29: SD1; S-2 | J29: PT where in contact with concrete.
A30: Wall framing | B30: Scheduled shear wall panel area | C30: SF | D30: =(4+4/12+10+6.5+5+9+12)*Measurements!B7 -> 374.66667 | E30: 0.1 | F30: =D30*(1+E30) -> 412.13333 | G30: Scheduled calculation | H30: S-3 / PDF 12 | J30: Six tagged lengths; gross panel area. 15/32 in structural panels.
A31: Joists | B31: New ceiling joist coverage, 2x10 @16 in OC | C31: SF | D31: =Measurements!B5 -> 563 | E31: 0 | F31: =D31*(1+E31) -> 563 | G31: Stated / plan | H31: S-3; A-6.1 | J31: Addition ceiling only; existing ceiling joists generally remain.
A32: Joists | B32: New ceiling joist lumber, area-based budget | C32: LF | D32: =D31/(16/12) -> 422.25 | E32: 0.1 | F32: =D32*(1+E32) -> 464.475 | G32: Allowance | H32: S-3 / PDF 12 | J32: Includes basic joist runs only; add double/sistered members separately.
A33: Joists | B33: Existing ceiling joist retained coverage | C33: SF | D33: =Measurements!B6 -> 908 | E33: 0 | F33: =D33*(1+E33) -> 908 | G33: Stated / existing | H33: S-3 / PDF 12 | J33: Existing 908 SF; localized sistering and beams require field lengths.
A34: Joists | B34: New raised-floor / floor joist area | C34: SF | D34: 0 | E34: 0 | F34: =D34*(1+E34) -> 0 | G34: Not shown | H34: S-2 / PDF 11 | J34: Slab-on-grade construction; no new framed floor indicated.
A35: Drywall | B35: New/altered wall gypsum net area | C35: SF | D35: =Measurements!B13-Measurements!B14+2*D24-2*Measurements!B15*Measurements!B16*Measurements!B17-2*Measurements!B18 -> 1530.6667 | E35: 0 | F35: =D35*(1+E35) -> 1530.6667 | G35: Calculated approx. | H35: A-3; A-6 | J35: Exterior interior face + both partition faces; deduct door openings and assumed shower backer.
A36: Drywall | B36: Ceiling gypsum: addition + remodel allowance | C36: SF | D36: =Measurements!B5+Measurements!B19 -> 628 | E36: 0 | F36: =D36*(1+E36) -> 628 | G36: Calculated + allowance | H36: A-3; S-3 | J36: Existing-house ceiling replacement beyond 65 SF not included.
A37: Drywall | B37: TOTAL installed gypsum board area | C37: SF | D37: =D35+D36 -> 2158.6667 | E37: 0.1 | F37: =D37*(1+E37) -> 2374.5333 | G37: Calculated approx. | H37: A-3; A-6 | J37: Wall and ceiling totals; shower backer separate.
A38: Drywall | B38: 4x8 gypsum sheet equivalent with waste | C38: EA | D38: =ROUNDUP(D37*(1+Measurements!B28)/32,0) -> 75 | E38: 0 | F38: =D38*(1+E38) -> 75 | G38: Material allowance | H38: Estimator calculation | J38: Sheet-equivalent budget; select actual thickness / board lengths.
A39: Drywall | B39: Shower cementitious backer wall area | C39: SF | D39: =2*Measurements!B18 -> 132 | E39: 0.1 | F39: =D39*(1+E39) -> 145.2 | G39: Allowance | H39: A-3 keynotes | J39: Waterproofing and tile finish also required.
A40: Stucco | B40: New exterior stucco net field area | C40: SF | D40: =Measurements!B13-Measurements!B14 -> 556 | E40: 0.1 | F40: =D40*(1+E40) -> 611.6 | G40: Calculated approx. | H40: A-5; A-6 | J40: CTS Rapid Set one-coat system to match existing; excludes added tie-in patch allowance.
A41: Stucco | B41: Stucco tie-in / repair patch | C41: SF | D41: 50 | E41: 0 | F41: =D41*(1+E41) -> 50 | G41: Allowance | H41: A-3; A-5 | J41: Confirm demolition edges and existing finish condition.
A42: Stucco | B42: Weather barrier and lath gross area | C42: SF | D42: =Measurements!B13 -> 613 | E42: 0.1 | F42: =D42*(1+E42) -> 674.3 | G42: Stated area | H42: A-5; A-6 | J42: No opening deduction for membrane/lath budgeting.
A43: Stucco | B43: Weep screed new exposed walls | C43: LF | D43: =Measurements!B8 -> 77 | E43: 0.1 | F43: =D43*(1+E43) -> 84.7 | G43: Scaled approx. | H43: A-5 detail 3 | J43: Verify transitions at existing-house junctions.
...

Sheet Measurements
A2: Measurement basis - 11653 Rivera Road
A4: Input / measurement | B4: Value | C4: Unit | D4: Basis | E4: Sheet / PDF page | F4: Method / limitation
A5: New addition gross floor area | B5: 563 | C5: SF | D5: Stated | E5: A-1 / PDF 1; A-6 / PDF 7 | F5: Authoritative project area; includes wall footprints.
A6: Existing conditioned house | B6: 908 | C6: SF | D6: Stated | E6: A-1 / PDF 1; A-6 / PDF 7 | F6: Existing house; garage excluded.
A7: Wall height | B7: 8 | C7: FT | D7: Stated | E7: A-5 / PDF 6; A-6 / PDF 7 | F7: Typical ceiling height.
A8: New exposed exterior footing length | B8: 77 | C8: LF | D8: Scaled approx. | E8: S-2 / PDF 11; A-6 CF1R p6 | F8: Trace of exposed stepped perimeter; energy report also lists 77 LF slab exposed perimeter.
A9: Interior longitudinal footing | B9: 22.3 | C9: LF | D9: Scaled approx. | E9: S-2 / PDF 11 | F9: Thickened line beneath east hall wall; section not independently specified.
A10: Slab connection / turned-down edge | B10: 25.8 | C10: LF | D10: Scaled approx. | E10: S-2 details 4-5 / PDF 11 | F10: Across existing-house interface; separate from exposed perimeter.
A11: New partitions within addition | B11: 64.2 | C11: LF | D11: Scaled approx. | E11: A-3 / PDF 4 | F11: Hall sides, bathroom walls and closet partitions; includes openings.
A12: New partitions in existing remodel | B12: 18.3 | C12: LF | D12: Scaled approx. | E12: A-3 / PDF 4 | F12: Walk-in closet and pantry alterations; retained walls excluded as practicable.
A13: New exterior wall gross area | B13: 613 | C13: SF | D13: Stated | E13: A-6 CF1R p4 / PDF 7 | F13: 203 left + 207 rear + 203 right; differs slightly from scaled length x height.
A14: New window opening area | B14: 57 | C14: SF | D14: Count x schedule | E14: A-3 / PDF 4 | F14: 4 windows x 3x4 + 2 windows x 3x1.5; energy model lists 58 SF.
A15: New hinged interior doors | B15: 6 | C15: EA | D15: Counted | E15: A-3 / PDF 4 | F15: 2 baths, 2 bedrooms, hall door and walk-in closet; excludes closet opening.
A16: Hinged door width | B16: 2.6666667 | C16: FT | D16: Stated | E16: A-3 door schedule / PDF 4 | F16: Confirm required accessible clear openings before procurement.
... A38: Aggregate base depth | B38: 4 | C38: IN | D38: Stated | E38: S-2 details 1 and 5 / PDF 11 | F38: 4 in clean aggregate.
