Workbook

Sheet Summary
A1: 492 W Altadena Drive - takeoff summary
A2: Powell Residence | House 2,006 SF | Garage 420 SF | Porch 134 SF
A4: Scope | B4: Net quantity | C4: Unit | D4: Basis | E4: Key note
A5: Continuous footings | B5: ='Trade quantities'!D9 -> 418.16667 | C5: LF | D5: Approximate | E5: Includes porch and garage; Hardy beam included once.
A6: Slab-on-grade, house + garage | B6: =Measurements!B5+Measurements!B6 -> 2426 | C6: SF | D6: Scheduled | E6: 4 inch slab; porch separate.
A7: Porch slab | B7: ='Trade quantities'!D13 -> 134 | C7: SF | D7: Scheduled | E7: Thickness allowance 4 inches.
A8: Total slabs including porch | B8: ='Trade quantities'!D14 -> 2560 | C8: SF | D8: Calculated | E8: Area only; footings are separate.
A9: Rectangular wall framing | B9: ='Trade quantities'!D24 -> 4451 | C9: SF | D9: Approximate | E9: One face; gables listed separately.
A10: Raised floor joists | B10: 0 | C10: SF | D10: Plan condition | E10: No raised-floor system shown.
A11: House + garage ceiling joists | B11: ='Trade quantities'!D33 -> 2426 | C11: SF | D11: Gross footprint | E11: Porch ceiling framing 134 SF separately.
A12: House drywall | B12: ='Trade quantities'!D37 -> 6816 | C12: SF | D12: Approximate | E12: Walls + ceilings; 10% purchase allowance in detail.
A13: Wall stucco | B13: ='Trade quantities'!D46 -> 2129.6667 | C13: SF | D13: Approximate | E13: Net openings and veneer allowance deducted.
A14: Sloped roofing | B14: ='Trade quantities'!D54 -> 3106.9378 | C14: SF | D14: Approximate | E14: 4:12 slope; eaves included.
A15: House floor coverings | B15: ='Trade quantities'!D61 -> 1855 | C15: SF | D15: Allowance | E15: Finish selections not specified.
A16: Drawn receptacle locations | B16: ='Trade quantities'!D70 -> 63 | C16: EA | D16: Counted | E16: Includes range/dryer; additional equipment points in detail.
A17: Recessed LED fixtures | B17: 44 | C17: EA | D17: Counted | E17: 40 house + 4 garage.
A18: Switch controls | B18: 32 | C18: EA | D18: Counted | E18: 6 dimmers + 8 three-way dimmers + 4 VS + 14 other.
A19: Plumbing bathrooms | B19: 2 | C19: EA | D19: Counted | E19: 2 WC, 4 lavatories, 1 primary tub, 1 shower, 1 tub/shower.
A20: Heat pump water heater | B20: 1 | C20: EA | D20: Specified | E20: 40 gal modeled; exterior architectural location.
A21: Central heat pump system | B21: 1 | C21: SET | D21: Specified | E21: 1 outdoor unit + 1 attic air handler.
A22: Exhaust fans | B22: 4 | C22: EA | D22: Counted | E22: Four fans including laundry.
A25: Items to confirm before final ordering
A27: Measurement limits | E27: Architectural general note says DO NOT SCALE DRAWINGS. Footing interiors, partition length, gables and roof-edge offsets use calibrated drawing traces/allowances; verify before bid commitment or order.
A28: Plan coordination | E28: A-1 scope says 4 bedrooms, while A-2 labels primary, bedroom #2 and bedroom #3. Takeoff follows drawn spaces and 5 shown smoke alarms.
A29: Opening schedules | E29: A-2 shows two D10 wardrobe openings, while A-2a lists one. Window #14 is shown but absent from A-2a. Opening deductions are allowances pending schedule correction.
A30: Water heater / recirculation | E30: T24a models 40 gal heat pump WH in living area and no recirculation. A-2 places WH in exterior enclosure and requires hot-water recirculation. Architect/energy consultant must reconcile.
A31: Mechanical capacity | E31: T24a gives 50,000 BTU/h heating, HSPF 8.8, SEER 15 and EER 12.2. Do not infer cooling tonnage from heating capacity; obtain equipment schedule and duct design.
A32: Purchase quantities | E32: Order column applies stated waste to each line. TOTAL rows already combine component net areas: do not add totals to component rows. EA counts have no waste unless explicitly stated.
A33: Unquantified scope | E33: Wire lengths/cable sizes, footing reinforcement and local pad/deepened footing volumes need detailed schedules/routes. No fabricated quantities are included.
A34: Other work shown | E34: NFPA 13D fire sprinklers and photovoltaics are deferred/separate scopes. Title 24 models 2.4 kW PV. Site concrete includes 2,150 SF driveway/patio, 545 SF path and 80 SF walk, outside requested foundation slabs.

Sheet Trade quantities
A1: 492 W Altadena Drive - construction takeoff
A2: Net quantities and purchase allowances are separate. Approximate measurements are not fabrication quantities.
A4: Trade | B4: Item / scope | C4: Unit | D4: Net quantity | E4: Waste / allowance | F4: Order quantity | G4: Basis | H4: Drawing / PDF page | I4: Method / inclusions
A5: Foundation | B5: House exterior continuous footing | C5: LF | D5: =Measurements!B11 -> 201.66667 | E5: 0 | F5: =D5*(1+E5) -> 201.66667 | G5: Calculated | H5: A-2 p6; S1 p15 | I5: Full continuous run, including openings; approximately 202 LF.
A6: Foundation | B6: House interior continuous footing | C6: LF | D6: =SUM(Measurements!B20,Measurements!B21,Measurements!B22,Measurements!B23) -> 103 | E6: 0 | F6: =D6*(1+E6) -> 103 | G6: Approximate | H6: S1 p15 | I6: Four traced interior runs; verify footing intersections and local widenings.
A7: Foundation | B7: Porch outer footing runs | C7: LF | D7: =Measurements!B24 -> 31.5 | E7: 0 | F7: =D7*(1+E7) -> 31.5 | G7: Approximate | H7: S1 p15 | I7: Entry footing configuration requires field/detail confirmation.
A8: Foundation | B8: Garage perimeter footing / grade beam | C8: LF | D8: =Measurements!B15 -> 82 | E8: 0 | F8: =D8*(1+E8) -> 82 | G8: Calculated | H8: S1 p15; A-2 p6 | I8: Includes garage-door grade beam.
A9: Foundation | B9: TOTAL continuous footings | C9: LF | D9: =SUM(D5:D8) -> 418.16667 | E9: 0 | F9: =D9*(1+E9) -> 418.16667 | G9: Approximate | H9: S1 p15 | I9: Counts each run once. Does not add Hardy grade-beam subset again.
A10: Foundation | B10: Hardy-frame grade beam (included above) | C10: LF | D10: =Measurements!B25 -> 20 | E10: 0 | F10: =D10*(1+E10) -> 20 | G10: Approximate | H10: D1/11 p17; D2/27 p18 | I10: 24 x 24 inch beam at garage opening; not an extra 20 LF.
A11: Foundation | B11: House slab-on-grade | C11: SF | D11: =Measurements!B5 -> 2006 | E11: 0 | F11: =D11*(1+E11) -> 2006 | G11: Scheduled | H11: A-1 p1; S1 p15 | I11: 4 inch net slab. Gross building footprint used; footing/slab overlap not deducted.
A12: Foundation | B12: Garage slab-on-grade | C12: SF | D12: =Measurements!B6 -> 420 | E12: 0 | F12: =D12*(1+E12) -> 420 | G12: Scheduled | H12: A-1 p1; S1 p15 | I12: 4 inch net slab.
A13: Foundation | B13: Porch slab | C13: SF | D13: =Measurements!B7 -> 134 | E13: 0 | F13: =D13*(1+E13) -> 134 | G13: Scheduled | H13: A-1 p1 | I13: Area scheduled; 4 inch thickness allowance.
A14: Foundation | B14: TOTAL house + garage + porch slab | C14: SF | D14: =SUM(D11:D13) -> 2560 | E14: 0 | F14: =D14*(1+E14) -> 2560 | G14: Calculated | H14: A-1 p1 | I14: Porch included separately above.
A15: Foundation | B15: House slab concrete only | C15: CY | D15: =D11*Measurements!B17/12/27 -> 24.765432 | E15: 0.05 | F15: =D15*(1+E15) -> 26.003704 | G15: Calculated | H15: S1 p15 | I15: Excludes footings, curbs, pads and thickened edges.
A16: Foundation | B16: Garage slab concrete only | C16: CY | D16: =D12*Measurements!B18/12/27 -> 5.1851852 | E16: 0.05 | F16: =D16*(1+E16) -> 5.4444444 | G16: Calculated | H16: S1 p15 | I16: Excludes perimeter footings/grade beam.
A17: Foundation | B17: Porch slab concrete only | C17: CY | D17: =D13*Measurements!B19/12/27 -> 1.654321 | E17: 0.05 | F17: =D17*(1+E17) -> 1.737037 | G17: Allowance | H17: A-1 p1 | I17: Confirm thickness and joint treatment.
A18: Foundation | B18: House + garage slab #4 reinforcing | C18: LF | D18: =(Measurements!B5+Measurements!B6)*2/1.5 -> 3234.6667 | E18: 0.15 | F18: =D18*(1+E18) -> 3719.8667 | G18: Approximate | H18: S1 p15 | I18: #4 at 18 inches each way; area method, 15% for laps/cuts. Excludes footing steel.
A19: Foundation | B19: House + garage slab vapor barrier | C19: SF | D19: =Measurements!B5+Measurements!B6 -> 2426 | E19: 0.1 | F19: =D19*(1+E19) -> 2668.6 | G19: Scheduled | H19: S1 p15 | I19: 10 mil under house and garage; lap allowance.
A20: Foundation | B20: House + garage 4 inch base | C20: CY | D20: =(Measurements!B5+Measurements!B6)*4/12/27 -> 29.950617 | E20: 0.1 | F20: =D20*(1+E20) -> 32.945679 | G20: Calculated | H20: S1 p15 | I20: House detail also shows 2 inch sand bed; confirm garage specification.
A21: Wall framing | B21: House exterior wall framing - one face | C21: SF | D21: =Measurements!B11*Measurements!B10 -> 1815 | E21: 0 | F21: =D21*(1+E21) -> 1815 | G21: Calculated | H21: A-2 p6; A-5 p10 | I21: Gross framing plane; openings retained, excludes gables.
A22: Wall framing | B22: House interior wall framing - one face | C22: SF | D22: =Measurements!B16*Measurements!B10 -> 1980 | E22: 0 | F22: =D22*(1+E22) -> 1980 | G22: Approximate | H22: A-2 p6 | I22: 220 LF centerline allowance x 9 ft; includes openings.
A23: Wall framing | B23: Garage exterior wall framing - one face | C23: SF | D23: =Measurements!B15*Measurements!B14 -> 656 | E23: 0 | F23: =D23*(1+E23) -> 656 | G23: Calculated | H23: A-2 p6; A-5 p10 | I23: Gross wall framing; garage openings retained.
A24: Wall framing | B24: TOTAL rectangular wall framing | C24: SF | D24: =SUM(D21:D23) -> 4451 | E24: 0 | F24: =D24*(1+E24) -> 4451 | G24: Approximate | H24: A-2 p6; A-5 p10 | I24: One-face measurement, not drywall two-face area.
A25: Wall framing | B25: House gable framing additional | C25: SF | D25: =Measurements!B26 -> 180 | E25: 0 | F25: =D25*(1+E25) -> 180 | G25: Approximate | H25: A-4 p9 | I25: Separate from rectangular wall framing.
A26: Wall framing | B26: Garage gable framing additional | C26: SF | D26: =Measurements!B13^2*(Measurements!B36/12)/2 -> 66.666667 | E26: 0 | F26: =D26*(1+E26) -> 66.666667 | G26: Calculated | H26: A-4 p9 | I26: Two triangular gables.
A27: Wall framing | B27: Stud positions at 16 inches OC | C27: EA | D27: =ROUNDUP((Measurements!B11+Measurements!B16+Measurements!B15)/(16/12),0) -> 378 | E27: 0.15 | F27: =D27*(1+E27) -> 434.7 | G27: Allowance | H27: S2 p16; T24a p11 | I27: For budgeting only. Extra for corners/cripples; not a cut list. 2x6 plumbing walls required.
A28: Wall framing | B28: Bottom + double top plate | C28: LF | D28: =3*(Measurements!B11+Measurements!B16+Measurements!B15) -> 1511 | E28: 0.1 | F28: =D28*(1+E28) -> 1662.1 | G28: Approximate | H28: S2 p16 | I28: Three plate runs; no opening deductions.
A29: Joists | B29: Raised floor joist area | C29: SF | D29: =Measurements!B40 -> 0 | E29: 0 | F29: =D29*(1+E29) -> 0 | G29: Plan condition | H29: S1 p15 | I29: Zero floor-joist scope shown: slab-on-grade.
A30: Joists | B30: House ceiling joist area | C30: SF | D30: =Measurements!B5 -> 2006 | E30: 0 | F30: =D30*(1+E30) -> 2006 | G30: Scheduled footprint | H30: S2 p16 | I30: 2x10 ceiling joists at 16 inches OC shown. Area is gross projected framing.
A31: Joists | B31: Garage ceiling joist area | C31: SF | D31: =Measurements!B6 -> 420 | E31: 0 | F31: =D31*(1+E31) -> 420 | G31: Scheduled footprint | H31: S2 p16 | I31: 2x10 ceiling joists at 16 inches OC shown.
A32: Joists | B32: Porch ceiling framing area | C32: SF | D32: =Measurements!B7 -> 134 | E32: 0 | F32: =D32*(1+E32) -> 134 | G32: Scheduled footprint | H32: S2 p16 | I32: Porch roof shows 2x6 rafters; ceiling framing area only, not a 2x10 material order.
A33: Joists | B33: TOTAL house + garage ceiling joist area | C33: SF | D33: =SUM(D30:D31) -> 2426 | E33: 0 | F33: =D33*(1+E33) -> 2426 | G33: Calculated | H33: S2 p16 | I33: Porch separate.
A34: Joists | B34: 2x10 ceiling joist length allowance | C34: LF | D34: =D33/(16/12) -> 1819.5 | E34: 0.1 | F34: =D34*(1+E34) -> 2001.45 | G34: Allowance | H34: S2 p16 | I34: Area/spacing method; excludes end/edge members, blocks and overlaps. No stock-length breakdown.
A35: Drywall | B35: House wall drywall, net allowance | C35: SF | D35: =D21+2*D22-Measurements!B27-Measurements!B30-Measurements!B31 -> 4810 | E35: 0 | F35: =D35*(1+E35) -> 4810 | G35: Approximate | H35: A-2 p6; A-2a p7 | I35: Exterior walls one interior face, partitions two faces; wet backer separate.
A36: Drywall | B36: House ceiling drywall | C36: SF | D36: =Measurements!B5 -> 2006 | E36: 0 | F36: =D36*(1+E36) -> 2006 | G36: Gross allowance | H36: A-2 p6 | I36: 1/2 inch minimum; gross area includes partition footprints.
A37: Drywall | B37: TOTAL house drywall | C37: SF | D37: =D35+D36 -> 6816 | E37: 0.1 | F37: =D37*(1+E37) -> 7497.6 | G37: Approximate | H37: A-2 p6 | I37: Does not include garage, porch or wet-area backer.
A38: Drywall | B38: House drywall 4 x 12 sheet equivalent | C38: EA | D38: =ROUNDUP(F37/48,0) -> 157 | E38: 0 | F38: =D38*(1+E38) -> 157 | G38: Calculated | H38: A-2 p6 | I38: Order area includes 10% waste. Thickness/rated splits require confirmation.
A39: Drywall | B39: Wet-area wall tile backer | C39: SF | D39: =Measurements!B31 -> 200 | E39: 0.1 | F39: =D39*(1+E39) -> 220 | G39: Allowance | H39: A-2 p6 note 4a | I39: Separate from gypsum-board total.
A40: Drywall | B40: Garage required rated wall drywall | C40: SF | D40: =Measurements!B32*Measurements!B14 -> 328 | E40: 0.1 | F40: =D40*(1+E40) -> 360.8 | G40: Approximate | H40: A-5 p10 1HRA/1HRB | I40: 5/8 inch Type X interior face of two rated wall runs.
A41: Drywall | B41: Garage remaining walls, optional finish | C41: SF | D41: =(Measurements!B15-Measurements!B32)*Measurements!B14-Measurements!B28 -> 195 | E41: 0.1 | F41: =D41*(1+E41) -> 214.5 | G41: Optional allowance | H41: A-2 p6 | I41: Confirm finish requirement; not part of house drywall.
...

Sheet Measurements
A1: 492 W Altadena Drive - measurement basis
A2: Source: Approved permitted 492 W ALTADENA PLANS V2_v1-3.pdf (20 pages; approval 02/02/2026).
A4: Measurement / assumption | B4: Value | C4: Unit | D4: Drawing / PDF page | E4: Basis | F4: Method / scope
A5: House gross floor area | B5: 2006 | C5: SF | D5: A-1 p1; A-2 p6 | E5: Scheduled | F5: Building area to exterior walls; not net floor finish.
A6: Garage gross floor area | B6: 420 | C6: SF | D6: A-1 p1; A-2 p6 | E6: Scheduled | F6: 20 x 21 ft detached garage.
A7: Front porch area | B7: 134 | C7: SF | D7: A-1 p1 | E7: Scheduled | F7: Porch slab thickness is an allowance.
A8: House overall length | B8: 68 | C8: FT | D8: A-2 p6 | E8: Dimension | F8: Overall including front projection.
A9: House overall width | B9: 32.833333 | C9: FT | D9: A-2 p6 | E9: Dimension | F9: Stepped outline has same perimeter as bounding rectangle.
A10: House wall height | B10: 9 | C10: FT | D10: A-2 p6; A-5 p10 | E10: Dimension | F10: Flat ceilings at 9 ft.
A11: House perimeter | B11: =2*(B8+B9) -> 201.66667 | C11: LF | D11: A-2 p6 | E11: Calculated | F11: 2 x (68 + 32 ft 10 in); excludes porch posts/enclosure.
A12: Garage length | B12: 21 | C12: FT | D12: A-2 p6 | E12: Dimension | F12: Exterior dimension.
A13: Garage width | B13: 20 | C13: FT | D13: A-2 p6 | E13: Dimension | F13: Exterior dimension.
A14: Garage wall height | B14: 8 | C14: FT | D14: A-5 p10 | E14: Dimension | F14: Wall height excluding gables.
A15: Garage perimeter | B15: =2*(B12+B13) -> 82 | C15: LF | D15: A-2 p6 | E15: Calculated | F15: Includes garage-door threshold grade beam.
A16: Interior partition length | B16: 220 | C16: LF | D16: A-2 p6 | E16: Approximate | F16: Rounded trace including door openings; allow +/- 10%; excludes exterior walls.
A17: House slab thickness | B17: 4 | C17: IN | D17: S1 p15 | E17: Specified | F17: 4 inch net slab; #4 at 18 inches each way.
A18: Garage slab thickness | B18: 4 | C18: IN | D18: S1 p15 | E18: Specified | F18: 4 inch net slab; #4 at 18 inches each way.
A19: Porch slab thickness | B19: 4 | C19: IN | D19: A-1 p1; S1 p15 | E19: Allowance | F19: Confirm porch slab section; not a scheduled thickness.
A20: Interior footing: bath cross wall | B20: 14.9 | C20: LF | D20: S1 p15 | E20: Approximate | F20: Full run across primary-bath upper wall including openings.
A21: Interior footing: bath return | B21: 11.5 | C21: LF | D21: S1 p15 | E21: Approximate | F21: Return below bath cross wall, above exterior recess.
A22: Interior footing: central cross wall | B22: 43.8 | C22: LF | D22: S1 p15 | E22: Approximate | F22: Cross-building thickened run including door openings.
A23: Interior footing: central longitudinal | B23: 32.8 | C23: LF | D23: S1 p15 | E23: Approximate | F23: Main continuous north-south interior run.
A24: Porch footing outer runs | B24: 31.5 | C24: LF | D24: S1 p15; A-2 p6 | E24: Approximate | F24: Two 9 ft returns plus 13.5 ft front run; verify continuity at entry.
A25: Garage special grade beam | B25: 20 | C25: LF | D25: S1 p15; D1/11 p17; D2/27 p18 | E25: Approximate | F25: Subset of garage perimeter, not additional length; 24 x 24 in Hardy-frame beam.
A26: House gable wall allowance | B26: 180 | C26: SF | D26: A-4 p9 | E26: Approximate | F26: Two principal end triangles at 4:12; verify stepped roof/gable intersections.
A27: House exterior opening area | B27: 325 | C27: SF | D27: A-2 p6; A-2a p7 | E27: Approximate | F27: Combined allowance for windows/exterior doors; arches approximated. Window #14 is shown but absent from A-2a.
... A36: Roof pitch rise per 12 | B36: 4 | C36: IN | D36: A-1 p1; A-4 p9 | E36: Specified | F36: 4:12 composite Class A roofing.
A37: Roof slope factor | B37: =SQRT(1+(B36/12)^2) -> 1.0540926 | C37: FACTOR | D37: A-4 p9 | E37: Calculated | F37: Square root of 1 + (4/12)^2.
A38: Floor finish area: dry rooms | B38: 1580 | C38: SF | D38: A-2 p6 | E38: Allowance | F38: Net allowance for bedrooms, closets, living, dining, kitchen and hall. Material not specified.
A39: Floor finish area: baths/laundry | B39: 275 | C39: SF | D39: A-2 p6 | E39: Allowance | F39: Approx primary bath 165, hall bath 75, laundry 35 SF. Material not specified.
A40: House floor joists | B40: 0 | C40: SF | D40: S1 p15 | E40: Plan condition | F40: Slab-on-grade; no raised floor framing shown.
A41: House Type X drywall allowance | B41: 0 | C41: SF | D41: A-2 p6; A-5 p10 | E41: Needs confirmation | F41: Do not assume zero scope: verify any rated house wall requirements near property lines.
